{"uuid": "f57b8a74-0799-4a4c-af11-9aeb65aa10c2", "children": ["932a244f-9e23-48da-ba23-b7945bdcbd97"], "befores": [{"name": "test_edit", "status": "broken", "statusDetails": {"message": "selenium.common.exceptions.WebDriverException: Message: chrome not reachable\n  (Session info: chrome=92.0.4515.107)\n\n", "trace": "  File \"C:\\python\\lib\\site-packages\\pluggy\\callers.py\", line 187, in _multicall\n    res = hook_impl.function(*args)\n  File \"C:\\python\\lib\\site-packages\\_pytest\\fixtures.py\", line 1126, in pytest_fixture_setup\n    result = call_fixture_func(fixturefunc, request, kwargs)\n  File \"C:\\python\\lib\\site-packages\\_pytest\\fixtures.py\", line 925, in call_fixture_func\n    fixture_result = next(generator)\n  File \"C:\\pycharm\\Automation_project\\testcases\\conftest.py\", line 19, in test_edit\n    browser.maximize_window()\n  File \"C:\\python\\lib\\site-packages\\selenium\\webdriver\\remote\\webdriver.py\", line 737, in maximize_window\n    self.execute(command, params)\n  File \"C:\\python\\lib\\site-packages\\selenium\\webdriver\\remote\\webdriver.py\", line 321, in execute\n    self.error_handler.check_response(response)\n  File \"C:\\python\\lib\\site-packages\\selenium\\webdriver\\remote\\errorhandler.py\", line 242, in check_response\n    raise exception_class(message, screen, stacktrace)\n"}, "start": 1629176099544, "stop": 1629176106162}], "start": 1629176099544, "stop": 1629176106190}